<?xml version="1.0"?>
<robot name="ex9-car">
    <!-- For Gazebo color -->
    <gazebo reference="base_link">
        <material>Gazebo/Blue</material>
    </gazebo>
    <gazebo reference="right_front_wheel">
        <material>Gazebo/Yellow</material>
    </gazebo>
    <gazebo reference="right_rear_wheel">
        <material>Gazebo/Yellow</material>
    </gazebo>
    <gazebo reference="left_front_wheel">
        <material>Gazebo/Yellow</material>
    </gazebo>
    <gazebo reference="left_rear_wheel">
        <material>Gazebo/Yellow</material>
    </gazebo>

    <material name="blue">
        <color rgba="0 0 0.8 1"/>
    </material>
    <material name="yellow">
        <color rgba="1 1 0 1"/>
    </material>

    <!-- Link -->
    <link name="base_link">
        
        <visual>
            <geometry>
                <box size="2 8 1"/>
                <!-- <mesh filename="package://pr2_description/meshes/gripper_v0/l_finger.dae"/> -->
            </geometry>
            <material name="blue"/>
            <origin rpy="0 0 0" xyz="0 0 1"/>
        </visual>

        <collision>
            <geometry>
                <box size="2 8 1"/>
            </geometry>
            <origin rpy="0 0 0" xyz="0 0 1"/>
        </collision>

        <inertial>
            <mass value="10"/>
            <!-- <inertia ixx="1.0" ixy="1.0" ixz="1.0" iyy="1.0" iyz="1.0" izz="1.0"/> -->
            <inertia ixx="0.0" ixy="0.0" ixz="0.0" iyy="0.0" iyz="0.0" izz="0.0"/>
        </inertial>

    </link>

    <link name="right_front_wheel">
        <visual>
            <geometry>
                <cylinder radius="1" length="1"/>
            </geometry>
            <material name="yellow"/>
            <origin rpy="0.0 1.57 0" xyz="0 0 0"/>
        </visual>

        <collision>
            <geometry>
                <cylinder radius="1" length="1"/>
            </geometry>
            <origin rpy="0.0 1.57 0" xyz="0 0 0"/>
        </collision>

        <inertial>
            <mass value="1"/>
            <inertia ixx="1.0" ixy="1.0" ixz="1.0" iyy="1.0" iyz="1.0" izz="1.0"/>
        </inertial>

    </link>

    <link name="right_rear_wheel">
        <visual>
            <geometry>
                <cylinder radius="1" length="1"/>
            </geometry>
            <material name="yellow"/>
            <origin rpy="0.0 1.57 0" xyz="0 0 0"/>
        </visual>

        <collision>
            <geometry>
                <cylinder radius="1" length="1"/>
            </geometry>
            <origin rpy="0.0 1.57 0" xyz="0 0 0"/>
        </collision>

        <inertial>
            <mass value="1"/>
            <inertia ixx="1.0" ixy="1.0" ixz="1.0" iyy="1.0" iyz="1.0" izz="1.0"/>
        </inertial>

    </link>

    <link name="left_front_wheel">
        <visual>
            <geometry>
                <cylinder radius="1" length="1"/>
            </geometry>
            <material name="yellow"/>
            <origin rpy="0.0 1.57 0" xyz="0 0 0"/>
        </visual>

        <collision>
            <geometry>
                <cylinder radius="1" length="1"/>
            </geometry>
            <origin rpy="0.0 1.57 0" xyz="0 0 0"/>
        </collision>

        <inertial>
            <mass value="1"/>
            <inertia ixx="1.0" ixy="1.0" ixz="1.0" iyy="1.0" iyz="1.0" izz="1.0"/>
        </inertial>

    </link>

    <link name="left_rear_wheel">
        <visual>
            <geometry>
                <cylinder radius="1" length="1"/>
            </geometry>
            <material name="yellow"/>
            <origin rpy="0.0 1.57 0" xyz="0 0 0"/>
        </visual>

        <collision>
            <geometry>
                <cylinder radius="1" length="1"/>
            </geometry>
            <origin rpy="0.0 1.57 0" xyz="0 0 0"/>
        </collision>

        <inertial>
            <mass value="1"/>
            <inertia ixx="1.0" ixy="1.0" ixz="1.0" iyy="1.0" iyz="1.0" izz="1.0"/>
        </inertial>

    </link>

    <!-- Joint -->
    <joint name="base_to_right_front_wheel" type="continuous">
        <parent link="base_link"/>
        <child link="right_front_wheel"/>
        <!-- Rotate clockwise -->
        <axis xyz="1 0 0"/>
        <origin xyz="-1.5 -1.5 1"/>
    </joint>
    <joint name="base_to_right_rear_wheel" type="continuous">
        <parent link="base_link"/>
        <child link="right_rear_wheel"/>
        <axis xyz="1 0 0"/>
        <origin xyz="-1.5 1.5 1"/>
    </joint>
    <joint name="base_to_left_front_wheel" type="continuous">
        <parent link="base_link"/>
        <child link="left_front_wheel"/>
        <axis xyz="1 0 0"/>
        <origin xyz="1.5 -1.5 1"/>
    </joint>
    <joint name="base_to_left_rear_wheel" type="continuous">
        <parent link="base_link"/>
        <child link="left_rear_wheel"/>
        <axis xyz="1 0 0"/>
        <origin xyz="1.5 1.5 1"/>
    </joint>

</robot>